<?xml version="1.0" encoding="utf-8"?>
<!-- This URDF was automatically created by SolidWorks to URDF Exporter! Originally created by Stephen Brawner (brawner@gmail.com) 
     Commit Version: 1.6.0-1-g15f4949  Build Version: 1.6.7594.29634
     For more information, please see http://wiki.ros.org/sw_urdf_exporter -->
<robot
  name="ntnu_leg">
  <!-- <link name="world"/> -->

  <link
    name="MH">
    <inertial>
      <origin
        xyz="0.091111 0.00024794 -0.030241"
        rpy="0 0 0" />
      <mass
        value="1.4057" />
      <inertia
        ixx="0.0010021"
        ixy="1.1E-06"
        ixz="-7.91E-06"
        iyy="0.004407"
        iyz="-6.01E-06"
        izz="0.0048417" />
    </inertial>
    <visual>
      <origin
        xyz="0 0 0"
        rpy="0 0 0" />
      <geometry>
        <mesh
          filename="meshes/MH.obj" />
      </geometry>
      <material
        name="">
        <color
          rgba="0.79216 0.81961 0.93333 1" />
      </material>
    </visual>
    <!-- <collision>
      <origin
        xyz="0 0 0"
        rpy="0 0 0" />
      <geometry>
        <mesh
          filename="meshes/MH_collisionSW.obj" />
      </geometry>
    </collision> -->
  </link>
  <!-- <joint
    name="jointMH"
    type="revolute">
    <origin
      xyz="0 0 1"
      rpy="1.57079632679  3.14159 0" />
    <parent
      link="world" />
    <child
      link="MH" />
    <axis
      xyz="1 0 0" />
    <limit
      lower="-1.57079632679"
      upper="1.57079632679"
      effort="100"
      velocity="1000" />
  </joint> -->
  <link
    name="link11">
    <inertial>
      <origin
        xyz="0.098421 -0.00092667 -0.00012402"
        rpy="0 0 0" />
      <mass
        value="0.10145" />
      <inertia
        ixx="9.3E-06"
        ixy="2.43E-06"
        ixz="-1.24E-06"
        iyy="0.00050506"
        iyz="1E-08"
        izz="0.00051065" />
    </inertial>
    <visual>
      <origin
        xyz="0 0 0"
        rpy="0 0 0" />
      <geometry>
        <mesh
          filename="meshes/link11.obj" />
      </geometry>
      <material
        name="">
        <color
          rgba="0.79216 0.81961 0.93333 1" />
      </material>
    </visual>
    <!-- <collision>
      <origin
        xyz="0 0 0"
        rpy="0 0 0" />
      <geometry>
        <mesh
          filename="meshes/link11_collisionSW.obj" />
      </geometry>
    </collision> -->
  </link>
  <joint
    name="joint11"
    type="revolute">
    <origin
      xyz="0.046 -1.1338E-05 -0.0597"
      rpy="3.1416 0 2.3095" />
    <parent
      link="MH" />
    <child
      link="link11" />
    <axis
      xyz="0 0 1" />
    <limit
      lower="-3.14"
      upper="3.14"
      effort="100"
      velocity="1000" />
  </joint>
  <link
    name="link21">
    <inertial>
      <origin
        xyz="0.20494 -0.021034 -2.714E-05"
        rpy="0 0 0" />
      <mass
        value="0.20117" />
      <inertia
        ixx="3.571E-05"
        ixy="9.52E-05"
        ixz="1.7E-07"
        iyy="0.0018983"
        iyz="-2E-08"
        izz="0.0019089" />
    </inertial>
    <visual>
      <origin
        xyz="0 0 0"
        rpy="0 0 0" />
      <geometry>
        <mesh
          filename="meshes/link21.obj" />
      </geometry>
      <material
        name="">
        <color
          rgba="0.79216 0.81961 0.93333 1" />
      </material>
    </visual>
    <!-- <collision>
      <origin
        xyz="0 0 0"
        rpy="0 0 0" />
      <geometry>
        <mesh
          filename="meshes/link21_collisionSW.obj" />
      </geometry>
    </collision> -->
  </link>
  <joint
    name="joint21"
    type="revolute">
    <origin
      xyz="0.18 0 0"
      rpy="0 0 1.3265" />
    <parent
      link="link11" />
    <child
      link="link21" />
    <axis
      xyz="0 0 1" />
    <limit
      lower="-2.85"
      upper="1.58"
      effort="100"
      velocity="1000" />
  </joint>
  <link
    name="link12">
    <inertial>
      <origin
        xyz="0.098201 0.00092745 -0.00012329"
        rpy="0 0 0" />
      <mass
        value="0.10205" />
      <inertia
        ixx="9.34E-06"
        ixy="-2.49E-06"
        ixz="-1.24E-06"
        iyy="0.00050784"
        iyz="-1E-08"
        izz="0.00051346" />
    </inertial>
    <visual>
      <origin
        xyz="0 0 0"
        rpy="0 0 0" />
      <geometry>
        <mesh
          filename="meshes/link12.obj" />
      </geometry>
      <material
        name="">
        <color
          rgba="0.79216 0.81961 0.93333 1" />
      </material>
    </visual>
    <!-- <collision>
      <origin
        xyz="0 0 0"
        rpy="0 0 0" />
      <geometry>
        <mesh
          filename="meshes/link12_collisionSW.obj" />
      </geometry>
    </collision> -->
  </link>
  <joint
    name="joint12"
    type="revolute">
    <origin
      xyz="0.136 -1.1338E-05 -0.0597"
      rpy="3.1416 0 0.83482" />
    <parent
      link="MH" />
    <child
      link="link12" />
    <axis
      xyz="0 0 1" />
    <limit
      lower="-3.14"
      upper="3.14"
      effort="100"
      velocity="1000" />
  </joint>
  <link
    name="link22">
    <inertial>
      <origin
        xyz="0.18647 0.0041966 0"
        rpy="0 0 0" />
      <mass
        value="0.13331" />
      <inertia
        ixx="1.73E-05"
        ixy="5.202E-05"
        ixz="0"
        iyy="0.0015703"
        iyz="0"
        izz="0.0015717" />
    </inertial>
    <visual>
      <origin
        xyz="0 0 0"
        rpy="0 0 0" />
      <geometry>
        <mesh
          filename="meshes/link22.obj" />
      </geometry>
      <material
        name="">
        <color
          rgba="0.79216 0.81961 0.93333 1" />
      </material>
    </visual>
    <!-- <collision>
      <origin
        xyz="0 0 0"
        rpy="0 0 0" />
      <geometry>
        <mesh
          filename="meshes/link22_collisionSW.obj" />
      </geometry>
    </collision> -->
  </link>
  <joint
    name="joint22"
    type="revolute">
    <origin
      xyz="0.18 0 0"
      rpy="0 0 -1.3233" />
    <parent
      link="link12" />
    <child
      link="link22" />
    <axis
      xyz="0 0 1" />
    <limit
      lower="-1.51"
      upper="2.9"
      effort="100"
      velocity="1000" />
  </joint>

<!-- Add self collision -->
<gazebo reference="link21">
  <selfCollide>true</selfCollide>
</gazebo>
<gazebo reference="link11">
  <selfCollide>true</selfCollide>
</gazebo>
<gazebo reference="link22">
  <selfCollide>true</selfCollide>
</gazebo>
<gazebo reference="link12">
  <selfCollide>true</selfCollide>
</gazebo>



</robot>